<mujoco><option>timestep="0.1"</option><worldbody><light diffuse=".5 .5 .5" dir="0 0 1" pos="0 0 3" /><geom name="floor" rgba="0 .39 0 1" size="100 100 0.1" type="plane" /><body name="head"><freejoint name="root" /><geom name="head" pos="0 0 0.4" rgba="1 .75 0 1" size="0.3 0.2 0.2" type="box" /><body name="body0Body" pos="0.65 0 0.4"><geom rgba="0.75 1 0 1" size="0.3 0.2 0.2" type="box" /><joint axis="0 0 1" limited="true" name="body0Joint" pos="-0.15 0 0" range="-20 20" /><body name="body0leg1"><geom pos="0.2 0.35 0.05" size="0.05 0.15 0.05" type="box" /><joint axis="1 0 0" limited="true" name="body0leg1Hinge" pos="0 0 0.5" range="-10 10" /><geom pos="0.2 0.45 -.1" size="0.05 0.05 0.2" type="box" /></body><body name="body0leg11" /><body name="body0leg2"><geom pos="-0.2 0.35 0.05" size="0.05 0.15 0.05" type="box" /><joint axis="1 0 0" limited="true" name="body0leg2Hinge" pos="0 0 0.5" range="-10 10" /><geom pos="-0.2 0.45 -.1" size="0.05 0.05 0.2" type="box" /></body><body name="body0leg21" /><body name="body0leg3"><geom pos="0.2 -0.35 0.05" size="0.05 0.15 0.05" type="box" /><joint axis="1 0 0" limited="true" name="body0leg3Hinge" pos="0 0 0.5" range="-10 10" /><geom pos="0.2 -0.45 -.1" size="0.05 0.05 0.2" type="box" /></body><body name="body0leg31" /><body name="body0leg4"><geom pos="-0.2 -0.35 0.05" size="0.05 0.15 0.05" type="box" /><joint axis="1 0 0" limited="true" name="body0leg4Hinge" pos="0 0 0.5" range="-10 10" /><geom pos="-0.2 -0.45 -.1" size="0.05 0.05 0.2" type="box" /></body><body name="body0leg41" /></body><body name="body1Body" pos="1.3 0 0.4"><geom rgba="0.75 1 0 1" size="0.3 0.2 0.2" type="box" /><joint axis="0 0 1" limited="true" name="body1Joint" pos="-0.15 0 0" range="-20 20" /><body name="body1leg1"><geom pos="0.2 0.35 0.05" size="0.05 0.15 0.05" type="box" /><joint axis="1 0 0" limited="true" name="body1leg1Hinge" pos="0 0 0.5" range="-10 10" /><geom pos="0.2 0.45 -.1" size="0.05 0.05 0.2" type="box" /></body><body name="body1leg11" /><body name="body1leg2"><geom pos="-0.2 0.35 0.05" size="0.05 0.15 0.05" type="box" /><joint axis="1 0 0" limited="true" name="body1leg2Hinge" pos="0 0 0.5" range="-10 10" /><geom pos="-0.2 0.45 -.1" size="0.05 0.05 0.2" type="box" /></body><body name="body1leg21" /><body name="body1leg3"><geom pos="0.2 -0.35 0.05" size="0.05 0.15 0.05" type="box" /><joint axis="1 0 0" limited="true" name="body1leg3Hinge" pos="0 0 0.5" range="-10 10" /><geom pos="0.2 -0.45 -.1" size="0.05 0.05 0.2" type="box" /></body><body name="body1leg31" /><body name="body1leg4"><geom pos="-0.2 -0.35 0.05" size="0.05 0.15 0.05" type="box" /><joint axis="1 0 0" limited="true" name="body1leg4Hinge" pos="0 0 0.5" range="-10 10" /><geom pos="-0.2 -0.45 -.1" size="0.05 0.05 0.2" type="box" /></body><body name="body1leg41" /></body><body name="body2Body" pos="1.9500000000000002 0 0.4"><geom rgba="0.75 1 0 1" size="0.3 0.2 0.2" type="box" /><joint axis="0 0 1" limited="true" name="body2Joint" pos="-0.15 0 0" range="-20 20" /><body name="body2leg1"><geom pos="0.2 0.35 0.05" size="0.05 0.15 0.05" type="box" /><joint axis="1 0 0" limited="true" name="body2leg1Hinge" pos="0 0 0.5" range="-10 10" /><geom pos="0.2 0.45 -.1" size="0.05 0.05 0.2" type="box" /></body><body name="body2leg11" /><body name="body2leg2"><geom pos="-0.2 0.35 0.05" size="0.05 0.15 0.05" type="box" /><joint axis="1 0 0" limited="true" name="body2leg2Hinge" pos="0 0 0.5" range="-10 10" /><geom pos="-0.2 0.45 -.1" size="0.05 0.05 0.2" type="box" /></body><body name="body2leg21" /><body name="body2leg3"><geom pos="0.2 -0.35 0.05" size="0.05 0.15 0.05" type="box" /><joint axis="1 0 0" limited="true" name="body2leg3Hinge" pos="0 0 0.5" range="-10 10" /><geom pos="0.2 -0.45 -.1" size="0.05 0.05 0.2" type="box" /></body><body name="body2leg31" /><body name="body2leg4"><geom pos="-0.2 -0.35 0.05" size="0.05 0.15 0.05" type="box" /><joint axis="1 0 0" limited="true" name="body2leg4Hinge" pos="0 0 0.5" range="-10 10" /><geom pos="-0.2 -0.45 -.1" size="0.05 0.05 0.2" type="box" /></body><body name="body2leg41" /></body><body name="body3Body" pos="2.6 0 0.4"><geom rgba="0.75 1 0 1" size="0.3 0.2 0.2" type="box" /><joint axis="0 0 1" limited="true" name="body3Joint" pos="-0.15 0 0" range="-20 20" /><body name="body3leg1"><geom pos="0.2 0.35 0.05" size="0.05 0.15 0.05" type="box" /><joint axis="1 0 0" limited="true" name="body3leg1Hinge" pos="0 0 0.5" range="-10 10" /><geom pos="0.2 0.45 -.1" size="0.05 0.05 0.2" type="box" /></body><body name="body3leg11" /><body name="body3leg2"><geom pos="-0.2 0.35 0.05" size="0.05 0.15 0.05" type="box" /><joint axis="1 0 0" limited="true" name="body3leg2Hinge" pos="0 0 0.5" range="-10 10" /><geom pos="-0.2 0.45 -.1" size="0.05 0.05 0.2" type="box" /></body><body name="body3leg21" /><body name="body3leg3"><geom pos="0.2 -0.35 0.05" size="0.05 0.15 0.05" type="box" /><joint axis="1 0 0" limited="true" name="body3leg3Hinge" pos="0 0 0.5" range="-10 10" /><geom pos="0.2 -0.45 -.1" size="0.05 0.05 0.2" type="box" /></body><body name="body3leg31" /><body name="body3leg4"><geom pos="-0.2 -0.35 0.05" size="0.05 0.15 0.05" type="box" /><joint axis="1 0 0" limited="true" name="body3leg4Hinge" pos="0 0 0.5" range="-10 10" /><geom pos="-0.2 -0.45 -.1" size="0.05 0.05 0.2" type="box" /></body><body name="body3leg41" /></body><body name="body4Body" pos="3.25 0 0.4"><geom rgba="0.75 1 0 1" size="0.3 0.2 0.2" type="box" /><joint axis="0 0 1" limited="true" name="body4Joint" pos="-0.15 0 0" range="-20 20" /><body name="body4leg1"><geom pos="0.2 0.35 0.05" size="0.05 0.15 0.05" type="box" /><joint axis="1 0 0" limited="true" name="body4leg1Hinge" pos="0 0 0.5" range="-10 10" /><geom pos="0.2 0.45 -.1" size="0.05 0.05 0.2" type="box" /></body><body name="body4leg11" /><body name="body4leg2"><geom pos="-0.2 0.35 0.05" size="0.05 0.15 0.05" type="box" /><joint axis="1 0 0" limited="true" name="body4leg2Hinge" pos="0 0 0.5" range="-10 10" /><geom pos="-0.2 0.45 -.1" size="0.05 0.05 0.2" type="box" /></body><body name="body4leg21" /><body name="body4leg3"><geom pos="0.2 -0.35 0.05" size="0.05 0.15 0.05" type="box" /><joint axis="1 0 0" limited="true" name="body4leg3Hinge" pos="0 0 0.5" range="-10 10" /><geom pos="0.2 -0.45 -.1" size="0.05 0.05 0.2" type="box" /></body><body name="body4leg31" /><body name="body4leg4"><geom pos="-0.2 -0.35 0.05" size="0.05 0.15 0.05" type="box" /><joint axis="1 0 0" limited="true" name="body4leg4Hinge" pos="0 0 0.5" range="-10 10" /><geom pos="-0.2 -0.45 -.1" size="0.05 0.05 0.2" type="box" /></body><body name="body4leg41" /></body><body name="body5Body" pos="3.9000000000000004 0 0.4"><geom rgba="0.75 1 0 1" size="0.3 0.2 0.2" type="box" /><joint axis="0 0 1" limited="true" name="body5Joint" pos="-0.15 0 0" range="-20 20" /><body name="body5leg1"><geom pos="0.2 0.35 0.05" size="0.05 0.15 0.05" type="box" /><joint axis="1 0 0" limited="true" name="body5leg1Hinge" pos="0 0 0.5" range="-10 10" /><geom pos="0.2 0.45 -.1" size="0.05 0.05 0.2" type="box" /></body><body name="body5leg11" /><body name="body5leg2"><geom pos="-0.2 0.35 0.05" size="0.05 0.15 0.05" type="box" /><joint axis="1 0 0" limited="true" name="body5leg2Hinge" pos="0 0 0.5" range="-10 10" /><geom pos="-0.2 0.45 -.1" size="0.05 0.05 0.2" type="box" /></body><body name="body5leg21" /><body name="body5leg3"><geom pos="0.2 -0.35 0.05" size="0.05 0.15 0.05" type="box" /><joint axis="1 0 0" limited="true" name="body5leg3Hinge" pos="0 0 0.5" range="-10 10" /><geom pos="0.2 -0.45 -.1" size="0.05 0.05 0.2" type="box" /></body><body name="body5leg31" /><body name="body5leg4"><geom pos="-0.2 -0.35 0.05" size="0.05 0.15 0.05" type="box" /><joint axis="1 0 0" limited="true" name="body5leg4Hinge" pos="0 0 0.5" range="-10 10" /><geom pos="-0.2 -0.45 -.1" size="0.05 0.05 0.2" type="box" /></body><body name="body5leg41" /></body><body name="body6Body" pos="4.55 0 0.4"><geom rgba="0.75 1 0 1" size="0.3 0.2 0.2" type="box" /><joint axis="0 0 1" limited="true" name="body6Joint" pos="-0.15 0 0" range="-20 20" /><body name="body6leg1"><geom pos="0.2 0.35 0.05" size="0.05 0.15 0.05" type="box" /><joint axis="1 0 0" limited="true" name="body6leg1Hinge" pos="0 0 0.5" range="-10 10" /><geom pos="0.2 0.45 -.1" size="0.05 0.05 0.2" type="box" /></body><body name="body6leg11" /><body name="body6leg2"><geom pos="-0.2 0.35 0.05" size="0.05 0.15 0.05" type="box" /><joint axis="1 0 0" limited="true" name="body6leg2Hinge" pos="0 0 0.5" range="-10 10" /><geom pos="-0.2 0.45 -.1" size="0.05 0.05 0.2" type="box" /></body><body name="body6leg21" /><body name="body6leg3"><geom pos="0.2 -0.35 0.05" size="0.05 0.15 0.05" type="box" /><joint axis="1 0 0" limited="true" name="body6leg3Hinge" pos="0 0 0.5" range="-10 10" /><geom pos="0.2 -0.45 -.1" size="0.05 0.05 0.2" type="box" /></body><body name="body6leg31" /><body name="body6leg4"><geom pos="-0.2 -0.35 0.05" size="0.05 0.15 0.05" type="box" /><joint axis="1 0 0" limited="true" name="body6leg4Hinge" pos="0 0 0.5" range="-10 10" /><geom pos="-0.2 -0.45 -.1" size="0.05 0.05 0.2" type="box" /></body><body name="body6leg41" /></body><body name="body7Body" pos="5.2 0 0.4"><geom rgba="0.75 1 0 1" size="0.3 0.2 0.2" type="box" /><joint axis="0 0 1" limited="true" name="body7Joint" pos="-0.15 0 0" range="-20 20" /><body name="body7leg1"><geom pos="0.2 0.35 0.05" size="0.05 0.15 0.05" type="box" /><joint axis="1 0 0" limited="true" name="body7leg1Hinge" pos="0 0 0.5" range="-10 10" /><geom pos="0.2 0.45 -.1" size="0.05 0.05 0.2" type="box" /></body><body name="body7leg11" /><body name="body7leg2"><geom pos="-0.2 0.35 0.05" size="0.05 0.15 0.05" type="box" /><joint axis="1 0 0" limited="true" name="body7leg2Hinge" pos="0 0 0.5" range="-10 10" /><geom pos="-0.2 0.45 -.1" size="0.05 0.05 0.2" type="box" /></body><body name="body7leg21" /><body name="body7leg3"><geom pos="0.2 -0.35 0.05" size="0.05 0.15 0.05" type="box" /><joint axis="1 0 0" limited="true" name="body7leg3Hinge" pos="0 0 0.5" range="-10 10" /><geom pos="0.2 -0.45 -.1" size="0.05 0.05 0.2" type="box" /></body><body name="body7leg31" /><body name="body7leg4"><geom pos="-0.2 -0.35 0.05" size="0.05 0.15 0.05" type="box" /><joint axis="1 0 0" limited="true" name="body7leg4Hinge" pos="0 0 0.5" range="-10 10" /><geom pos="-0.2 -0.45 -.1" size="0.05 0.05 0.2" type="box" /></body><body name="body7leg41" /></body></body></worldbody><actuator><motor gear="10" joint="body0Joint" name="body0Hinge" /><motor gear="100" joint="body0leg1Hinge" name="body0leg1Hinge" /><motor gear="100" joint="body0leg2Hinge" name="body0leg2Hinge" /><motor gear="100" joint="body0leg3Hinge" name="body0leg3Hinge" /><motor gear="100" joint="body0leg4Hinge" name="body0leg4Hinge" /><motor gear="10" joint="body1Joint" name="body1Hinge" /><motor gear="100" joint="body1leg1Hinge" name="body1leg1Hinge" /><motor gear="100" joint="body1leg2Hinge" name="body1leg2Hinge" /><motor gear="100" joint="body1leg3Hinge" name="body1leg3Hinge" /><motor gear="100" joint="body1leg4Hinge" name="body1leg4Hinge" /><motor gear="10" joint="body2Joint" name="body2Hinge" /><motor gear="100" joint="body2leg1Hinge" name="body2leg1Hinge" /><motor gear="100" joint="body2leg2Hinge" name="body2leg2Hinge" /><motor gear="100" joint="body2leg3Hinge" name="body2leg3Hinge" /><motor gear="100" joint="body2leg4Hinge" name="body2leg4Hinge" /><motor gear="10" joint="body3Joint" name="body3Hinge" /><motor gear="100" joint="body3leg1Hinge" name="body3leg1Hinge" /><motor gear="100" joint="body3leg2Hinge" name="body3leg2Hinge" /><motor gear="100" joint="body3leg3Hinge" name="body3leg3Hinge" /><motor gear="100" joint="body3leg4Hinge" name="body3leg4Hinge" /><motor gear="10" joint="body4Joint" name="body4Hinge" /><motor gear="100" joint="body4leg1Hinge" name="body4leg1Hinge" /><motor gear="100" joint="body4leg2Hinge" name="body4leg2Hinge" /><motor gear="100" joint="body4leg3Hinge" name="body4leg3Hinge" /><motor gear="100" joint="body4leg4Hinge" name="body4leg4Hinge" /><motor gear="10" joint="body5Joint" name="body5Hinge" /><motor gear="100" joint="body5leg1Hinge" name="body5leg1Hinge" /><motor gear="100" joint="body5leg2Hinge" name="body5leg2Hinge" /><motor gear="100" joint="body5leg3Hinge" name="body5leg3Hinge" /><motor gear="100" joint="body5leg4Hinge" name="body5leg4Hinge" /><motor gear="10" joint="body6Joint" name="body6Hinge" /><motor gear="100" joint="body6leg1Hinge" name="body6leg1Hinge" /><motor gear="100" joint="body6leg2Hinge" name="body6leg2Hinge" /><motor gear="100" joint="body6leg3Hinge" name="body6leg3Hinge" /><motor gear="100" joint="body6leg4Hinge" name="body6leg4Hinge" /><motor gear="10" joint="body7Joint" name="body7Hinge" /><motor gear="100" joint="body7leg1Hinge" name="body7leg1Hinge" /><motor gear="100" joint="body7leg2Hinge" name="body7leg2Hinge" /><motor gear="100" joint="body7leg3Hinge" name="body7leg3Hinge" /><motor gear="100" joint="body7leg4Hinge" name="body7leg4Hinge" /></actuator></mujoco>